<?xml version="1.0" ?>
<!-- =================================================================================== -->
<!-- |    This document was autogenerated by xacro from camera_velodyne.urdf.xacro     | -->
<!-- |    EDITING THIS FILE BY HAND IS NOT RECOMMENDED                                 | -->
<!-- =================================================================================== -->
<robot name="camera_velodyne" xmlns:xacro="http://ros.org/wiki/xacro">
  <!-- constants for robot dimentions  -->
  <!-- inertial for box -->
  <!-- inertial for cylinder -->
  <!-- import Rviz color -->
  <material name="white">
    <color rgba="1 1 1 1"/>
  </material>
  <material name="gray">
    <color rgba="0.4 0.4 0.4 1"/>
  </material>
  <material name="lightgray">
    <color rgba="0.45 0.45 0.45 1"/>
  </material>
  <material name="ivory">
    <color rgba="0.54 0.53 0.56 1"/>
  </material>
  <material name="darkgray">
    <color rgba="0.35 0.35 0.35 1"/>
  </material>
  <material name="black">
    <color rgba="0.2 0.2 0.2 1"/>
  </material>
  <material name="laser_black">
    <color rgba="0.1 0.1 0.1 0.0.6"/>
  </material>
  <material name="blue">
    <color rgba="0 0 0.8 1"/>
  </material>
  <material name="red">
    <color rgba="0.8 0 0 1"/>
  </material>
  <material name="green">
    <color rgba="0 0.8 0 1"/>
  </material>
  <material name="yellow">
    <color rgba="0.8 0.8 0 1"/>
  </material>
  <material name="cyan">
    <color rgba="0 0.8 0.8 0.8"/>
  </material>
  <material name="purple">
    <color rgba="0.8 0 0.8 1"/>
  </material>
  <!-- import all Gazebo-customization elements, including Gazebo colors -->
  <gazebo reference="velodyne_base_link">
    <material>Gazebo/Gold</material>
    <mu1>0.0</mu1>
    <mu2>0.0</mu2>
  </gazebo>
  <gazebo reference="velodyne_top_link">
    <material>Gazebo/Gold</material>
    <mu1>0.0</mu1>
    <mu2>0.0</mu2>
  </gazebo>
  <gazebo reference="velodyne_laser_link">
    <material>Gazebo/Black</material>
  </gazebo>
  <gazebo reference="camera_base_link">
    <material>Gazebo/Gray</material>
  </gazebo>
  <gazebo reference="lens_link">
    <material>Gazebo/Black</material>
  </gazebo>
  <!-- velodyne -->
  <gazebo reference="velodyne_laser_core_link">
    <sensor name="head_velodyne_sensor" type="ray">
      <visualize>false</visualize>
      <update_rate>1</update_rate>
      <ray>
        <scan>
          <horizontal>
            <samples>1080</samples>
            <resolution>1</resolution>
            <min_angle>-3.1415</min_angle>
            <max_angle>3.1415</max_angle>
          </horizontal>
          <vertical>
            <samples>32</samples>
            <resolution>1</resolution>
            <min_angle>-0.186227</min_angle>
            <max_angle>0.535292</max_angle>
          </vertical>
        </scan>
        <range>
          <min>0.10</min>
          <max>70.0</max>
          <resolution>0.01</resolution>
        </range>
        <noise>
          <type>gaussian</type>
          <mean>0.0</mean>
          <stddev>0.01</stddev>
        </noise>
      </ray>
      <plugin filename="libgazebo_ros_block_laser.so" name="gazebo_ros_head_velodyne_controller">
        <alwaysOn>true</alwaysOn>
        <updateRate>1</updateRate>
        <topicName>velodyne_points</topicName>
        <frameName>velodyne_laser_core_link</frameName>
      </plugin>
    </sensor>
  </gazebo>
  <!-- camera -->
  <gazebo reference="lens_link">
    <sensor name="camera1" type="camera">
      <update_rate>30.0</update_rate>
      <camera name="usb_cam">
        <horizontal_fov>1.3962634</horizontal_fov>
        <image>
          <width>800</width>
          <height>800</height>
          <format>R8G8B8</format>
        </image>
        <clip>
          <near>0.02</near>
          <far>300</far>
        </clip>
        <noise>
          <type>gaussian</type>
          <!-- Noise is sampled independently per pixel on each frame.
					That pixel's noise value is added to each of its color
					channels, which at that point lie in the range [0,1]. -->
          <mean>0.0</mean>
          <stddev>0.007</stddev>
        </noise>
      </camera>
      <plugin filename="libgazebo_ros_camera.so" name="camera_controller">
        <alwaysOn>true</alwaysOn>
        <updateRate>0.0</updateRate>
        <cameraName>usb_cam</cameraName>
        <imageTopicName>image_raw</imageTopicName>
        <cameraInfoTopicName>camera_info</cameraInfoTopicName>
        <frameName>lens_link</frameName>
        <hackBaseline>0.07</hackBaseline>
        <distortionK1>0.0</distortionK1>
        <distortionK2>0.0</distortionK2>
        <distortionK3>0.0</distortionK3>
        <distortionT1>0.0</distortionT1>
        <distortionT2>0.0</distortionT2>
      </plugin>
    </sensor>
  </gazebo>
  <!-- ros_control plugin -->
  <gazebo>
    <plugin filename="libgazebo_ros_control.so" name="gazebo_ros_control">
      <robotNamespace>/infant</robotNamespace>
    </plugin>
  </gazebo>
  <link name="world"/>
  <joint name="fixed" type="fixed">
    <parent link="world"/>
    <child link="base_link"/>
    <origin rpy="0 0 0" xyz="0 0 0"/>
  </joint>
  <!-- camera velodyne model  -->
  <link name="base_link"/>
  <joint name="base2velodyne_base" type="fixed">
    <parent link="base_link"/>
    <child link="velodyne_base_link"/>
    <origin rpy="0 0 0" xyz="0 0 1.26415665"/>
  </joint>
  <!-- velodyne -->
  <link name="velodyne_base_link">
    <visual>
      <geometry>
        <cylinder length="0.058674" radius="0.042672"/>
      </geometry>
      <origin rpy="0 0 0" xyz="0 0 0.029337"/>
      <material name="darkgray"/>
    </visual>
    <collision>
      <geometry>
        <cylinder length="0.058674" radius="0.042672"/>
      </geometry>
      <origin rpy="0 0 0" xyz="0 0 0.029337"/>
    </collision>
    <inertial>
      <origin rpy="0 0 0" xyz="0.0 0.0 0.029337"/>
      <mass value="1.0"/>
      <inertia ixx="1.0" ixy="0.0" ixz="0.0" iyy="1.0" iyz="0.0" izz="1.0"/>
    </inertial>
  </link>
  <joint name="velodyne_top_joint" type="continuous">
    <parent link="velodyne_base_link"/>
    <child link="velodyne_top_link"/>
    <origin rpy="0 0 0" xyz="0 0 0.058674"/>
    <axis xyz="0 0 1"/>
  </joint>
  <link name="velodyne_top_link">
    <visual>
      <geometry>
        <mesh filename="package://camera_velodyne_calibration_gazebo/meshes/velodyne_top.dae"/>
      </geometry>
      <origin rpy="1.570796 0 0" xyz="0 0 0"/>
    </visual>
    <collision>
      <geometry>
        <cylinder length="0.0835714" radius="0.042672"/>
      </geometry>
      <origin rpy="0 0 0" xyz="0 0 0.0417857"/>
    </collision>
    <inertial>
      <origin rpy="0 0 0" xyz="0.0 0.0 0.0417857"/>
      <mass value="0.0001"/>
      <inertia ixx="1.0" ixy="0.0" ixz="0.0" iyy="1.0" iyz="0.0" izz="1.0"/>
    </inertial>
  </link>
  <joint name="velodyne_laser_joint" type="fixed">
    <parent link="velodyne_top_link"/>
    <child link="velodyne_laser_link"/>
    <origin rpy="0 0 0" xyz="0 0 0.02716935"/>
  </joint>
  <link name="velodyne_laser_link">
    <visual>
      <geometry>
        <box size="0.03475311 0.0468099 0.0404979"/>
      </geometry>
      <origin rpy="0 0 0" xyz="0.017376555 0 0"/>
      <material name="lase_black"/>
    </visual>
    <collision>
      <geometry>
        <box size="0.03475311 0.0468099 0.0404979"/>
      </geometry>
      <origin rpy="0 0 0" xyz="0.017376555 0 0"/>
    </collision>
    <inertial>
      <origin rpy="0 0 0" xyz="0.017376555 0.0 0.0"/>
      <mass value="0.0001"/>
      <inertia ixx="1.0" ixy="0.0" ixz="0.0" iyy="1.0" iyz="0.0" izz="1.0"/>
    </inertial>
  </link>
  <joint name="velodyne_base2velodyne_laser_core" type="fixed">
    <parent link="velodyne_base_link"/>
    <child link="velodyne_laser_core_link"/>
    <origin rpy="0 0 0" xyz="0 0 0.08584335"/>
  </joint>
  <link name="velodyne_laser_core_link"/>
  <!-- monocular camera -->
  <joint name="base2camera" type="fixed">
    <parent link="base_link"/>
    <child link="camera_base_link"/>
    <origin rpy="0 0 0" xyz="0.35 0.015 1.1"/>
  </joint>
  <link name="camera_base_link">
    <visual>
      <geometry>
        <box size="0.020 0.070 0.030"/>
      </geometry>
      <origin rpy="0 0 0" xyz="0 0 0"/>
      <material name="darkgray"/>
    </visual>
    <inertial>
      <origin rpy="0 0 0" xyz="0.0 0.0 0.0"/>
      <mass value="0.01"/>
      <inertia ixx="1.0" ixy="0.0" ixz="0.0" iyy="1.0" iyz="0.0" izz="1.0"/>
    </inertial>
  </link>
  <joint name="camera_base2lens" type="fixed">
    <parent link="camera_base_link"/>
    <child link="lens_link"/>
    <origin rpy="0 0 0" xyz="0 -0.015 0"/>
  </joint>
  <link name="lens_link">
    <visual>
      <geometry>
        <cylinder length="0.017" radius="0.010"/>
      </geometry>
      <origin rpy="0 1.570796 0" xyz="0.005 0 0"/>
      <material name="laser_black"/>
    </visual>
    <inertial>
      <origin rpy="0 0 0" xyz="0.005 0.0 0.0"/>
      <mass value="0.0001"/>
      <inertia ixx="1.0" ixy="0.0" ixz="0.0" iyy="1.0" iyz="0.0" izz="1.0"/>
    </inertial>
  </link>
  <transmission name="velodyne_top_trans">
    <type>transmission_interface/SimpleTransmission</type>
    <joint name="velodyne_top_joint">
      <hardwareInterface>VelocityJointInterface</hardwareInterface>
    </joint>
    <actuator name="velodyne_top_motor">
      <hardwareInterface>VelocityJointInterface</hardwareInterface>
      <mechanicalReduction>1</mechanicalReduction>
    </actuator>
  </transmission>
</robot>

